/home/gabriellbramley/FHIaims_GAB/builds/mkl_scalapack_oneapi_lib/
['/home/gabriellbramley/FHIaims_GAB/builds/mkl_scalapack_oneapi_lib/libaims.240206.scalapack.mpi.so']
/home/gabriellbramley/FHIaims_GAB/builds/mkl_scalapack_oneapi_lib/
['/home/gabriellbramley/FHIaims_GAB/builds/mkl_scalapack_oneapi_lib/libaims.240206.scalapack.mpi.so']
Traceback (most recent call last):
Traceback (most recent call last):
  File "/home/gabriellbramley/python_scripts/asi_embedding/test/asi_test/test.py", line 38, in <module>
    atoms.calc = ASI_ASE_calculator(ASI_LIB_PATH, init_via_ase, MPI.COMM_WORLD, atoms, work_dir="./", logfile="aims.out")
  File "/home/gabriellbramley/python_envs/mace-venv/lib/python3.9/site-packages/asi4py/asecalc.py", line 28, in __init__
  File "/home/gabriellbramley/python_scripts/asi_embedding/test/asi_test/test.py", line 38, in <module>
    self.asi.init()
      File "/home/gabriellbramley/python_envs/mace-venv/lib/python3.9/site-packages/asi4py/pyasi.py", line 149, in init
atoms.calc = ASI_ASE_calculator(ASI_LIB_PATH, init_via_ase, MPI.COMM_WORLD, atoms, work_dir="./", logfile="aims.out")
  File "/home/gabriellbramley/python_envs/mace-venv/lib/python3.9/site-packages/asi4py/asecalc.py", line 28, in __init__
        self.asi.init()
self.lib = CDLL(self.lib_file, mode=RTLD_GLOBAL)
  File "/opt/intel/oneapi/intelpython/latest/lib/python3.9/ctypes/__init__.py", line 382, in __init__
    self._handle = _dlopen(self._name, mode)
OSError: /opt/intel/oneapi/intelpython/python3.9/bin/../lib/libstdc++.so.6: version `GLIBCXX_3.4.29' not found (required by /home/gabriellbramley/FHIaims_GAB/builds/mkl_scalapack_oneapi_lib/subdirectory_aims1/build/libaims1.so)
  File "/home/gabriellbramley/python_envs/mace-venv/lib/python3.9/site-packages/asi4py/pyasi.py", line 149, in init
    self.lib = CDLL(self.lib_file, mode=RTLD_GLOBAL)
  File "/opt/intel/oneapi/intelpython/latest/lib/python3.9/ctypes/__init__.py", line 382, in __init__
    self._handle = _dlopen(self._name, mode)
OSError: /opt/intel/oneapi/intelpython/python3.9/bin/../lib/libstdc++.so.6: version `GLIBCXX_3.4.29' not found (required by /home/gabriellbramley/FHIaims_GAB/builds/mkl_scalapack_oneapi_lib/subdirectory_aims1/build/libaims1.so)
Exception ignored in: <function ASI_ASE_calculator.__del__ at 0x14af7a9519d0>
Traceback (most recent call last):
  File "/home/gabriellbramley/python_envs/mace-venv/lib/python3.9/site-packages/asi4py/asecalc.py", line 76, in __del__
  File "/home/gabriellbramley/python_envs/mace-venv/lib/python3.9/site-packages/asi4py/asecalc.py", line 73, in close
  File "/home/gabriellbramley/python_envs/mace-venv/lib/python3.9/site-packages/asi4py/pyasi.py", line 192, in close
AttributeError: 'ASIlib' object has no attribute 'lib'
Exception ignored in: <function ASI_ASE_calculator.__del__ at 0x1498200689d0>
Traceback (most recent call last):
  File "/home/gabriellbramley/python_envs/mace-venv/lib/python3.9/site-packages/asi4py/asecalc.py", line 76, in __del__
  File "/home/gabriellbramley/python_envs/mace-venv/lib/python3.9/site-packages/asi4py/asecalc.py", line 73, in close
  File "/home/gabriellbramley/python_envs/mace-venv/lib/python3.9/site-packages/asi4py/pyasi.py", line 192, in close
AttributeError: 'ASIlib' object has no attribute 'lib'
